package lab.sam.example;
public class Main {
	public static void main(String[] args) {
		ExceptionEx eex = new ExceptionEx();
		eex.method();
		//System.out.println("프로그램 종료");
	}
}

class ExceptionEx{
	void method() {
		try{
			method1();
		}catch(Exception e) {
			System.out.println("method()에서 예외가 발생하였습니다.");
			//e.printStackTrace();
		}
	}
	void method1() throws Exception{
		method2();
	}
	void method2() throws Exception{
		try {
		throw new Exception();
		//throw new RuntimeException();	
	}catch(Exception e){
		System.out.println("method2()에서 예외처리 되었습니다.");
		e.printStackTrace();
		throw e;
	}
}
	void methodFin() {
		try {
			System.out.println("method() 실행");
			return;
//			throw new RuntimeException();
		}catch(Exception e) {
			System.out.println("method().catch{}실행");
//			e.printStackTrace();
		}finally {	//finally는 어느상황에서든지 실행시켜줌
			System.out.println("method().finally{}실행");
		}
	}
	void methodThrow(){
//		try {
//		Exception e=new Exception("예외");
//		throw e;	//예외를 발생시킨다
//		}catch(Exception e) {
//			System.out.println("예외처리");
//		}
		throw new RuntimeException();
		
	}
	void methodOrder() {
		System.out.println(1);
		try {
		System.out.println(2);
		System.out.println(0/0);	//에러발생시 3번 뛰어 넘음
		System.out.println(3);
		}catch(Exception e) {
//			System.out.println(4);		//에러발생하지 않으면 때문에 출력x
			//e.printStackTrace();
			System.out.println("예외 메세지 : "+e.getMessage());
		}
		System.out.println(5);
	}
	void methodAex() {
		int number =100;
		int result=0;
		
		int idx=0;
		while(idx<10) {
			try {
			result = number/(int)(Math.random()*10);
			System.out.println("result: "+result);
			}
			catch(ArithmeticException ae) {
				System.out.println("0으로 나눌수 없습니다.");	//jump 후 실행
			}
			idx++;
		}
	}
	//예외처리
//	Exception in thread "main" java.lang.ArithmeticException: / by zero		==> zero가원인
//	at lab.sam.example.ExceptionEx.method(Main.java:17)		==> 17번째 줄이 원인
//	at lab.sam.example.Main.main(Main.java:5)
	void methodFrame() {
		try {
			try {
				
			}catch(Exception e) {
				
			}
		}catch(Exception e) {
			try {
				
			}catch(Exception ee) {
				
			}
		}

	}
}
